[2025-03-04T07:02:39.564+0000] {local_task_job_runner.py:123} INFO - ::group::Pre task execution logs
[2025-03-04T07:02:39.583+0000] {taskinstance.py:2614} INFO - Dependencies all met for dep_context=non-requeueable deps ti=<TaskInstance: mini_snow_staging.data_staging manual__2025-03-04T07:02:34.217483+00:00 [queued]>
[2025-03-04T07:02:39.607+0000] {taskinstance.py:2614} INFO - Dependencies all met for dep_context=requeueable deps ti=<TaskInstance: mini_snow_staging.data_staging manual__2025-03-04T07:02:34.217483+00:00 [queued]>
[2025-03-04T07:02:39.609+0000] {taskinstance.py:2867} INFO - Starting attempt 1 of 1
[2025-03-04T07:02:39.626+0000] {taskinstance.py:2890} INFO - Executing <Task(BashOperator): data_staging> on 2025-03-04 07:02:34.217483+00:00
[2025-03-04T07:02:39.636+0000] {warnings.py:112} WARNING - /home/***/.local/lib/python3.12/site-packages/***/task/task_runner/standard_task_runner.py:70: DeprecationWarning: This process (pid=376) is multi-threaded, use of fork() may lead to deadlocks in the child.
  pid = os.fork()

[2025-03-04T07:02:39.638+0000] {standard_task_runner.py:72} INFO - Started process 386 to run task
[2025-03-04T07:02:39.638+0000] {standard_task_runner.py:104} INFO - Running: ['***', 'tasks', 'run', 'mini_snow_staging', 'data_staging', 'manual__2025-03-04T07:02:34.217483+00:00', '--job-id', '2', '--raw', '--subdir', 'DAGS_FOLDER/transform_and_analysis.py', '--cfg-path', '/tmp/tmpupxd0l2g']
[2025-03-04T07:02:39.640+0000] {standard_task_runner.py:105} INFO - Job 2: Subtask data_staging
[2025-03-04T07:02:39.660+0000] {warnings.py:112} WARNING - /home/***/.local/lib/python3.12/site-packages/***/settings.py:209: DeprecationWarning: The sql_alchemy_conn option in [core] has been moved to the sql_alchemy_conn option in [database] - the old setting has been used, but please update your config.
  SQL_ALCHEMY_CONN = conf.get("database", "SQL_ALCHEMY_CONN")

[2025-03-04T07:02:39.936+0000] {task_command.py:467} INFO - Running <TaskInstance: mini_snow_staging.data_staging manual__2025-03-04T07:02:34.217483+00:00 [running]> on host 8b83efa08de4
[2025-03-04T07:02:40.033+0000] {taskinstance.py:3134} INFO - Exporting env vars: AIRFLOW_CTX_DAG_OWNER='***' AIRFLOW_CTX_DAG_ID='mini_snow_staging' AIRFLOW_CTX_TASK_ID='data_staging' AIRFLOW_CTX_EXECUTION_DATE='2025-03-04T07:02:34.217483+00:00' AIRFLOW_CTX_TRY_NUMBER='1' AIRFLOW_CTX_DAG_RUN_ID='manual__2025-03-04T07:02:34.217483+00:00'
[2025-03-04T07:02:40.035+0000] {logging_mixin.py:190} INFO - Task instance is in running state
[2025-03-04T07:02:40.035+0000] {logging_mixin.py:190} INFO -  Previous state of the Task instance: queued
[2025-03-04T07:02:40.036+0000] {logging_mixin.py:190} INFO - Current task name:data_staging state:running start_date:2025-03-04 07:02:39.598820+00:00
[2025-03-04T07:02:40.037+0000] {logging_mixin.py:190} INFO - Dag name:mini_snow_staging and current dag run status:running
[2025-03-04T07:02:40.038+0000] {taskinstance.py:732} INFO - ::endgroup::
[2025-03-04T07:02:40.040+0000] {subprocess.py:78} INFO - Tmp dir root location: /tmp
[2025-03-04T07:02:40.041+0000] {subprocess.py:88} INFO - Running command: ['/usr/bin/bash', '-c', 'cd /opt/***/dbt && dbt run --models staging --profiles-dir .']
[2025-03-04T07:02:40.055+0000] {subprocess.py:99} INFO - Output:
[2025-03-04T07:02:43.218+0000] {subprocess.py:106} INFO - [0m07:02:43  Running with dbt=1.9.2
[2025-03-04T07:02:44.623+0000] {subprocess.py:106} INFO - [0m07:02:44  Registered adapter: snowflake=1.9.1
[2025-03-04T07:02:46.480+0000] {subprocess.py:106} INFO - [0m07:02:46  Encountered an error:
[2025-03-04T07:02:46.481+0000] {subprocess.py:106} INFO - 'dbt_snowpro://macros/generate_schema_name.sql'
[2025-03-04T07:02:46.481+0000] {subprocess.py:106} INFO - [0m07:02:46  Traceback (most recent call last):
[2025-03-04T07:02:46.482+0000] {subprocess.py:106} INFO -   File "/home/***/.local/lib/python3.12/site-packages/dbt/cli/requires.py", line 153, in wrapper
[2025-03-04T07:02:46.483+0000] {subprocess.py:106} INFO -     result, success = func(*args, **kwargs)
[2025-03-04T07:02:46.484+0000] {subprocess.py:106} INFO -                       ^^^^^^^^^^^^^^^^^^^^^
[2025-03-04T07:02:46.485+0000] {subprocess.py:106} INFO -   File "/home/***/.local/lib/python3.12/site-packages/dbt/cli/requires.py", line 103, in wrapper
[2025-03-04T07:02:46.485+0000] {subprocess.py:106} INFO -     return func(*args, **kwargs)
[2025-03-04T07:02:46.486+0000] {subprocess.py:106} INFO -            ^^^^^^^^^^^^^^^^^^^^^
[2025-03-04T07:02:46.486+0000] {subprocess.py:106} INFO -   File "/home/***/.local/lib/python3.12/site-packages/dbt/cli/requires.py", line 235, in wrapper
[2025-03-04T07:02:46.487+0000] {subprocess.py:106} INFO -     return func(*args, **kwargs)
[2025-03-04T07:02:46.487+0000] {subprocess.py:106} INFO -            ^^^^^^^^^^^^^^^^^^^^^
[2025-03-04T07:02:46.488+0000] {subprocess.py:106} INFO -   File "/home/***/.local/lib/python3.12/site-packages/dbt/cli/requires.py", line 264, in wrapper
[2025-03-04T07:02:46.488+0000] {subprocess.py:106} INFO -     return func(*args, **kwargs)
[2025-03-04T07:02:46.488+0000] {subprocess.py:106} INFO -            ^^^^^^^^^^^^^^^^^^^^^
[2025-03-04T07:02:46.489+0000] {subprocess.py:106} INFO -   File "/home/***/.local/lib/python3.12/site-packages/dbt/cli/requires.py", line 311, in wrapper
[2025-03-04T07:02:46.490+0000] {subprocess.py:106} INFO -     return func(*args, **kwargs)
[2025-03-04T07:02:46.490+0000] {subprocess.py:106} INFO -            ^^^^^^^^^^^^^^^^^^^^^
[2025-03-04T07:02:46.491+0000] {subprocess.py:106} INFO -   File "/home/***/.local/lib/python3.12/site-packages/dbt/cli/requires.py", line 327, in wrapper
[2025-03-04T07:02:46.491+0000] {subprocess.py:106} INFO -     setup_manifest(ctx, write=write, write_perf_info=write_perf_info)
[2025-03-04T07:02:46.492+0000] {subprocess.py:106} INFO -   File "/home/***/.local/lib/python3.12/site-packages/dbt/cli/requires.py", line 351, in setup_manifest
[2025-03-04T07:02:46.492+0000] {subprocess.py:106} INFO -     ctx.obj["manifest"] = parse_manifest(
[2025-03-04T07:02:46.493+0000] {subprocess.py:106} INFO -                           ^^^^^^^^^^^^^^^
[2025-03-04T07:02:46.493+0000] {subprocess.py:106} INFO -   File "/home/***/.local/lib/python3.12/site-packages/dbt/parser/manifest.py", line 2069, in parse_manifest
[2025-03-04T07:02:46.493+0000] {subprocess.py:106} INFO -     manifest = ManifestLoader.get_full_manifest(
[2025-03-04T07:02:46.494+0000] {subprocess.py:106} INFO -                ^^^^^^^^^^^^^^^^^^^^^^^^^^^^^^^^^
[2025-03-04T07:02:46.494+0000] {subprocess.py:106} INFO -   File "/home/***/.local/lib/python3.12/site-packages/dbt/parser/manifest.py", line 312, in get_full_manifest
[2025-03-04T07:02:46.494+0000] {subprocess.py:106} INFO -     manifest = loader.load()
[2025-03-04T07:02:46.495+0000] {subprocess.py:106} INFO -                ^^^^^^^^^^^^^
[2025-03-04T07:02:46.495+0000] {subprocess.py:106} INFO -   File "/home/***/.local/lib/python3.12/site-packages/dbt/parser/manifest.py", line 381, in load
[2025-03-04T07:02:46.496+0000] {subprocess.py:106} INFO -     self.load_and_parse_macros(project_parser_files)
[2025-03-04T07:02:46.496+0000] {subprocess.py:106} INFO -   File "/home/***/.local/lib/python3.12/site-packages/dbt/parser/manifest.py", line 683, in load_and_parse_macros
[2025-03-04T07:02:46.497+0000] {subprocess.py:106} INFO -     block = FileBlock(self.manifest.files[file_id])
[2025-03-04T07:02:46.497+0000] {subprocess.py:106} INFO -                       ~~~~~~~~~~~~~~~~~~~^^^^^^^^^
[2025-03-04T07:02:46.497+0000] {subprocess.py:106} INFO - KeyError: 'dbt_snowpro://macros/generate_schema_name.sql'
[2025-03-04T07:02:46.498+0000] {subprocess.py:106} INFO - 
[2025-03-04T07:02:48.558+0000] {subprocess.py:110} INFO - Command exited with return code 2
[2025-03-04T07:02:48.569+0000] {taskinstance.py:3313} ERROR - Task failed with exception
Traceback (most recent call last):
  File "/home/airflow/.local/lib/python3.12/site-packages/airflow/models/taskinstance.py", line 768, in _execute_task
    result = _execute_callable(context=context, **execute_callable_kwargs)
             ^^^^^^^^^^^^^^^^^^^^^^^^^^^^^^^^^^^^^^^^^^^^^^^^^^^^^^^^^^^^^
  File "/home/airflow/.local/lib/python3.12/site-packages/airflow/models/taskinstance.py", line 734, in _execute_callable
    return ExecutionCallableRunner(
           ^^^^^^^^^^^^^^^^^^^^^^^^
  File "/home/airflow/.local/lib/python3.12/site-packages/airflow/utils/operator_helpers.py", line 252, in run
    return self.func(*args, **kwargs)
           ^^^^^^^^^^^^^^^^^^^^^^^^^^
  File "/home/airflow/.local/lib/python3.12/site-packages/airflow/models/baseoperator.py", line 424, in wrapper
    return func(self, *args, **kwargs)
           ^^^^^^^^^^^^^^^^^^^^^^^^^^^
  File "/home/airflow/.local/lib/python3.12/site-packages/airflow/operators/bash.py", line 276, in execute
    raise AirflowException(
airflow.exceptions.AirflowException: Bash command failed. The command returned a non-zero exit code 2.
[2025-03-04T07:02:48.573+0000] {logging_mixin.py:190} INFO - Task instance in failure state
[2025-03-04T07:02:48.575+0000] {logging_mixin.py:190} INFO - Task start:2025-03-04 07:02:39.598820+00:00 end:2025-03-04 07:02:48.573386+00:00 duration:8.974566
[2025-03-04T07:02:48.576+0000] {logging_mixin.py:190} INFO - Task:<Task(BashOperator): data_staging> dag:<DAG: mini_snow_staging> dagrun:<DagRun mini_snow_staging @ 2025-03-04 07:02:34.217483+00:00: manual__2025-03-04T07:02:34.217483+00:00, state:running, queued_at: 2025-03-04 07:02:34.251841+00:00. externally triggered: True>
[2025-03-04T07:02:48.577+0000] {logging_mixin.py:190} INFO - Failure caused by Bash command failed. The command returned a non-zero exit code 2.
[2025-03-04T07:02:48.577+0000] {taskinstance.py:1226} INFO - Marking task as FAILED. dag_id=mini_snow_staging, task_id=data_staging, run_id=manual__2025-03-04T07:02:34.217483+00:00, execution_date=20250304T070234, start_date=20250304T070239, end_date=20250304T070248
[2025-03-04T07:02:48.615+0000] {taskinstance.py:341} INFO - ::group::Post task execution logs
[2025-03-04T07:02:48.617+0000] {standard_task_runner.py:124} ERROR - Failed to execute job 2 for task data_staging (Bash command failed. The command returned a non-zero exit code 2.; 386)
Traceback (most recent call last):
  File "/home/airflow/.local/lib/python3.12/site-packages/airflow/task/task_runner/standard_task_runner.py", line 117, in _start_by_fork
    ret = args.func(args, dag=self.dag)
          ^^^^^^^^^^^^^^^^^^^^^^^^^^^^^
  File "/home/airflow/.local/lib/python3.12/site-packages/airflow/cli/cli_config.py", line 49, in command
    return func(*args, **kwargs)
           ^^^^^^^^^^^^^^^^^^^^^
  File "/home/airflow/.local/lib/python3.12/site-packages/airflow/utils/cli.py", line 116, in wrapper
    return f(*args, **kwargs)
           ^^^^^^^^^^^^^^^^^^
  File "/home/airflow/.local/lib/python3.12/site-packages/airflow/cli/commands/task_command.py", line 483, in task_run
    task_return_code = _run_task_by_selected_method(args, _dag, ti)
                       ^^^^^^^^^^^^^^^^^^^^^^^^^^^^^^^^^^^^^^^^^^^^
  File "/home/airflow/.local/lib/python3.12/site-packages/airflow/cli/commands/task_command.py", line 256, in _run_task_by_selected_method
    return _run_raw_task(args, ti)
           ^^^^^^^^^^^^^^^^^^^^^^^
  File "/home/airflow/.local/lib/python3.12/site-packages/airflow/cli/commands/task_command.py", line 341, in _run_raw_task
    return ti._run_raw_task(
           ^^^^^^^^^^^^^^^^^
  File "/home/airflow/.local/lib/python3.12/site-packages/airflow/utils/session.py", line 97, in wrapper
    return func(*args, session=session, **kwargs)
           ^^^^^^^^^^^^^^^^^^^^^^^^^^^^^^^^^^^^^^
  File "/home/airflow/.local/lib/python3.12/site-packages/airflow/models/taskinstance.py", line 3006, in _run_raw_task
    return _run_raw_task(
           ^^^^^^^^^^^^^^
  File "/home/airflow/.local/lib/python3.12/site-packages/airflow/models/taskinstance.py", line 274, in _run_raw_task
    TaskInstance._execute_task_with_callbacks(
  File "/home/airflow/.local/lib/python3.12/site-packages/airflow/models/taskinstance.py", line 3161, in _execute_task_with_callbacks
    result = self._execute_task(context, task_orig)
             ^^^^^^^^^^^^^^^^^^^^^^^^^^^^^^^^^^^^^^
  File "/home/airflow/.local/lib/python3.12/site-packages/airflow/models/taskinstance.py", line 3185, in _execute_task
    return _execute_task(self, context, task_orig)
           ^^^^^^^^^^^^^^^^^^^^^^^^^^^^^^^^^^^^^^^
  File "/home/airflow/.local/lib/python3.12/site-packages/airflow/models/taskinstance.py", line 768, in _execute_task
    result = _execute_callable(context=context, **execute_callable_kwargs)
             ^^^^^^^^^^^^^^^^^^^^^^^^^^^^^^^^^^^^^^^^^^^^^^^^^^^^^^^^^^^^^
  File "/home/airflow/.local/lib/python3.12/site-packages/airflow/models/taskinstance.py", line 734, in _execute_callable
    return ExecutionCallableRunner(
           ^^^^^^^^^^^^^^^^^^^^^^^^
  File "/home/airflow/.local/lib/python3.12/site-packages/airflow/utils/operator_helpers.py", line 252, in run
    return self.func(*args, **kwargs)
           ^^^^^^^^^^^^^^^^^^^^^^^^^^
  File "/home/airflow/.local/lib/python3.12/site-packages/airflow/models/baseoperator.py", line 424, in wrapper
    return func(self, *args, **kwargs)
           ^^^^^^^^^^^^^^^^^^^^^^^^^^^
  File "/home/airflow/.local/lib/python3.12/site-packages/airflow/operators/bash.py", line 276, in execute
    raise AirflowException(
airflow.exceptions.AirflowException: Bash command failed. The command returned a non-zero exit code 2.
[2025-03-04T07:02:48.656+0000] {local_task_job_runner.py:266} INFO - Task exited with return code 1
[2025-03-04T07:02:48.680+0000] {taskinstance.py:3901} INFO - 0 downstream tasks scheduled from follow-on schedule check
[2025-03-04T07:02:48.685+0000] {local_task_job_runner.py:245} INFO - ::endgroup::
